<?xml version='1.0'?>
<sdf version='1.6'>
  <model name='sawyer'>
    <link name='base'>
      <pose frame=''>0 0 0 0 -0 0</pose>
      <inertial>
        <pose frame=''>-2.1e-05 -1e-06 -0.481414 0 -0 0</pose>
        <mass>62.9327</mass>
        <inertia>
          <ixx>5.70994</ixx>
          <ixy>0.000992111</ixy>
          <ixz>0.802702</ixz>
          <iyy>6.73327</iyy>
          <iyz>0.0011007</iyz>
          <izz>4.96932</izz>
        </inertia>
      </inertial>
      <velocity_decay/>
      <gravity>1</gravity>
      <velocity_decay/>
      <self_collide>1</self_collide>
      <enable_wind>0</enable_wind>
      <kinematic>0</kinematic>
      <visual name='base_fixed_joint_lump__right_arm_base_link_visual_1'>
        <pose frame=''>0 0 0 0 -0 0</pose>
        <geometry>
          <mesh>
            <scale>1 1 1</scale>
            <uri>model://sawyer/meshes/sawyer_pv/base.DAE</uri>
          </mesh>
        </geometry>
        <transparency>0</transparency>
        <cast_shadows>1</cast_shadows>
      </visual>
      <!-- <visual name='base_fixed_joint_lump__pedestal_visual'>
        <pose frame=''>0.26 0.345 -0.91488 1.5708 0 -1.5708</pose>
        <geometry>
          <mesh>
            <scale>1 1 1</scale>
            <uri>model://sawyer/meshes/sawyer_pv/pedestal.DAE</uri>
          </mesh>
        </geometry>
        <material>
          <script>
            <name>Gazebo/FlatBlack</name>
            <uri>file://media/materials/scripts/gazebo.material</uri>
          </script>
        </material>
        <transparency>0</transparency>
        <cast_shadows>1</cast_shadows>
      </visual> -->
      <visual name='base_cylinder'>
        <pose frame=''>0 0 -0.5 0 -0 0</pose>
        <geometry>
          <cylinder>
            <radius>0.15</radius>
            <length>1.0</length>
          </cylinder>
        </geometry>
        <!-- <material>
          <lighting>1</lighting>
          <script>
            <uri>file://media/materials/scripts/gazebo.material</uri>
            <name>Gazebo/Grey</name>
          </script>
          <shader type='vertex'>
            <normal_map>__default__</normal_map>
          </shader>
          <ambient>0.3 0.3 0.3 1</ambient>
          <diffuse>0.7 0.7 0.7 1</diffuse>
          <specular>0.01 0.01 0.01 1</specular>
          <emissive>0 0 0 1</emissive>
        </material> -->
        <transparency>0</transparency>
        <cast_shadows>1</cast_shadows>
      </visual>
      <visual name='base_fixed_joint_lump__torso_visual_2'>
        <pose frame=''>0 0 0 0 -0 0</pose>
        <geometry>
          <box>
            <size>0.001 0.001 0.001</size>
          </box>
        </geometry>
        <transparency>0</transparency>
        <cast_shadows>1</cast_shadows>
      </visual>
      <!-- <collision name='base_fixed_joint_lump__controller_box_collision'>
        <laser_retro>0</laser_retro>
        <max_contacts>10</max_contacts>
        <pose frame=''>-0.325 0 -0.38 0 -0 0</pose>
        <geometry>
          <box>
            <size>0.22 0.4 0.53</size>
          </box>
        </geometry>
        <surface>
          <friction>
            <ode>
              <mu>1</mu>
              <mu2>1</mu2>
              <fdir1>0 0 0</fdir1>
              <slip1>0</slip1>
              <slip2>0</slip2>
            </ode>
            <torsional>
              <coefficient>1</coefficient>
              <patch_radius>0</patch_radius>
              <surface_radius>0</surface_radius>
              <use_patch_radius>1</use_patch_radius>
              <ode>
                <slip>0</slip>
              </ode>
            </torsional>
          </friction>
          <bounce>
            <restitution_coefficient>0</restitution_coefficient>
            <threshold>1e+06</threshold>
          </bounce>
          <contact>
            <collide_without_contact>0</collide_without_contact>
            <collide_without_contact_bitmask>1</collide_without_contact_bitmask>
            <collide_bitmask>1</collide_bitmask>
            <ode>
              <soft_cfm>0</soft_cfm>
              <soft_erp>0.2</soft_erp>
              <kp>1e+13</kp>
              <kd>1</kd>
              <max_vel>0.01</max_vel>
              <min_depth>0</min_depth>
            </ode>
            <bullet>
              <split_impulse>1</split_impulse>
              <split_impulse_penetration_threshold>-0.01</split_impulse_penetration_threshold>
              <soft_cfm>0</soft_cfm>
              <soft_erp>0.2</soft_erp>
              <kp>1e+13</kp>
              <kd>1</kd>
            </bullet>
          </contact>
        </surface>
      </collision>
      <collision name='base_fixed_joint_lump__pedestal_feet_collision_1'>
        <laser_retro>0</laser_retro>
        <max_contacts>10</max_contacts>
        <pose frame=''>-0.1225 0 -0.758 0 -0 0</pose>
        <geometry>
          <box>
            <size>0.77 0.7 0.31</size>
          </box>
        </geometry>
        <surface>
          <friction>
            <ode>
              <mu>1</mu>
              <mu2>1</mu2>
              <fdir1>0 0 0</fdir1>
              <slip1>0</slip1>
              <slip2>0</slip2>
            </ode>
            <torsional>
              <coefficient>1</coefficient>
              <patch_radius>0</patch_radius>
              <surface_radius>0</surface_radius>
              <use_patch_radius>1</use_patch_radius>
              <ode>
                <slip>0</slip>
              </ode>
            </torsional>
          </friction>
          <bounce>
            <restitution_coefficient>0</restitution_coefficient>
            <threshold>1e+06</threshold>
          </bounce>
          <contact>
            <collide_without_contact>0</collide_without_contact>
            <collide_without_contact_bitmask>1</collide_without_contact_bitmask>
            <collide_bitmask>1</collide_bitmask>
            <ode>
              <soft_cfm>0</soft_cfm>
              <soft_erp>0.2</soft_erp>
              <kp>1e+13</kp>
              <kd>1</kd>
              <max_vel>0.01</max_vel>
              <min_depth>0</min_depth>
            </ode>
            <bullet>
              <split_impulse>1</split_impulse>
              <split_impulse_penetration_threshold>-0.01</split_impulse_penetration_threshold>
              <soft_cfm>0</soft_cfm>
              <soft_erp>0.2</soft_erp>
              <kp>1e+13</kp>
              <kd>1</kd>
            </bullet>
          </contact>
        </surface>
      </collision>
      <collision name='base_fixed_joint_lump__pedestal_collision_2'>
        <laser_retro>0</laser_retro>
        <max_contacts>10</max_contacts>
        <pose frame=''>-0.02 0 -0.29 0 -0 0</pose>
        <geometry>
          <cylinder>
            <radius>0.18</radius>
            <length>0.62</length>
          </cylinder>
        </geometry>
        <surface>
          <friction>
            <ode>
              <mu>1</mu>
              <mu2>1</mu2>
              <fdir1>0 0 0</fdir1>
              <slip1>0</slip1>
              <slip2>0</slip2>
            </ode>
            <torsional>
              <coefficient>1</coefficient>
              <patch_radius>0</patch_radius>
              <surface_radius>0</surface_radius>
              <use_patch_radius>1</use_patch_radius>
              <ode>
                <slip>0</slip>
              </ode>
            </torsional>
          </friction>
          <bounce>
            <restitution_coefficient>0</restitution_coefficient>
            <threshold>1e+06</threshold>
          </bounce>
          <contact>
            <collide_without_contact>0</collide_without_contact>
            <collide_without_contact_bitmask>1</collide_without_contact_bitmask>
            <collide_bitmask>1</collide_bitmask>
            <ode>
              <soft_cfm>0</soft_cfm>
              <soft_erp>0.2</soft_erp>
              <kp>1e+13</kp>
              <kd>1</kd>
              <max_vel>0.01</max_vel>
              <min_depth>0</min_depth>
            </ode>
            <bullet>
              <split_impulse>1</split_impulse>
              <split_impulse_penetration_threshold>-0.01</split_impulse_penetration_threshold>
              <soft_cfm>0</soft_cfm>
              <soft_erp>0.2</soft_erp>
              <kp>1e+13</kp>
              <kd>1</kd>
            </bullet>
          </contact>
        </surface>
      </collision>
      <collision name='base_fixed_joint_lump__right_arm_base_link_collision_3'>
        <laser_retro>0</laser_retro>
        <max_contacts>10</max_contacts>
        <pose frame=''>0 0 0.12 0 -0 0</pose>
        <geometry>
          <cylinder>
            <radius>0.08</radius>
            <length>0.24</length>
          </cylinder>
        </geometry>
        <surface>
          <friction>
            <ode>
              <mu>1</mu>
              <mu2>1</mu2>
              <fdir1>0 0 0</fdir1>
              <slip1>0</slip1>
              <slip2>0</slip2>
            </ode>
            <torsional>
              <coefficient>1</coefficient>
              <patch_radius>0</patch_radius>
              <surface_radius>0</surface_radius>
              <use_patch_radius>1</use_patch_radius>
              <ode>
                <slip>0</slip>
              </ode>
            </torsional>
          </friction>
          <bounce>
            <restitution_coefficient>0</restitution_coefficient>
            <threshold>1e+06</threshold>
          </bounce>
          <contact>
            <collide_without_contact>0</collide_without_contact>
            <collide_without_contact_bitmask>1</collide_without_contact_bitmask>
            <collide_bitmask>1</collide_bitmask>
            <ode>
              <soft_cfm>0</soft_cfm>
              <soft_erp>0.2</soft_erp>
              <kp>1e+13</kp>
              <kd>1</kd>
              <max_vel>0.01</max_vel>
              <min_depth>0</min_depth>
            </ode>
            <bullet>
              <split_impulse>1</split_impulse>
              <split_impulse_penetration_threshold>-0.01</split_impulse_penetration_threshold>
              <soft_cfm>0</soft_cfm>
              <soft_erp>0.2</soft_erp>
              <kp>1e+13</kp>
              <kd>1</kd>
            </bullet>
          </contact>
        </surface>
      </collision> -->
    </link>
    <!-- <link name='head'>
      <pose frame=''>0 -0 0.3765 0 -0 0</pose>
      <inertial>
        <pose frame=''>0.005321 -2.7e-05 0.1021 0 -0 0</pose>
        <mass>1.5795</mass>
        <inertia>
          <ixx>0.011833</ixx>
          <ixy>-4.4669e-06</ixy>
          <ixz>4.9425e-05</ixz>
          <iyy>0.0082709</iyy>
          <iyz>4.2124e-07</iyz>
          <izz>0.0049661</izz>
        </inertia>
      </inertial>
      <velocity_decay/>
      <gravity>1</gravity>
      <velocity_decay/>
      <sensor name='head_camera' type='camera'>
        <update_rate>10</update_rate>
        <camera name='head_camera'>
          <horizontal_fov>2.00787</horizontal_fov>
          <image>
            <width>1280</width>
            <height>800</height>
            <format>R8G8B8</format>
          </image>
          <clip>
            <near>0.1</near>
            <far>50</far>
          </clip>
        </camera>
        <pose frame=''>0.022803 0 0.216572 0 0.558504 0</pose>
      </sensor>
      <self_collide>0</self_collide>
      <enable_wind>0</enable_wind>
      <kinematic>0</kinematic>
      <visual name='head_fixed_joint_lump__screen_visual_1'>
        <pose frame=''>0.03 0 0.105 1.5708 -0 1.5708</pose>
        <geometry>
          <box>
            <size>0.24 0.14 0.002</size>
          </box>
        </geometry>
        <transparency>0</transparency>
        <cast_shadows>1</cast_shadows>
      </visual>
      <visual name='head_visual'>
        <pose frame=''>0 0 0 0 -0 0</pose>
        <geometry>
          <mesh>
            <scale>1 1 1</scale>
            <uri>model://sawyer/meshes/sawyer_pv/head.DAE</uri>
          </mesh>
        </geometry>
        <transparency>0</transparency>
        <cast_shadows>1</cast_shadows>
      </visual> -->
      <!-- <collision name='head_collision'>
        <laser_retro>0</laser_retro>
        <max_contacts>10</max_contacts>
        <pose frame=''>0 0 0.08 0 -0 0</pose>
        <geometry>
          <sphere>
            <radius>0.18</radius>
          </sphere>
        </geometry>
        <surface>
          <friction>
            <ode>
              <mu>1</mu>
              <mu2>1</mu2>
              <fdir1>0 0 0</fdir1>
              <slip1>0</slip1>
              <slip2>0</slip2>
            </ode>
            <torsional>
              <coefficient>1</coefficient>
              <patch_radius>0</patch_radius>
              <surface_radius>0</surface_radius>
              <use_patch_radius>1</use_patch_radius>
              <ode>
                <slip>0</slip>
              </ode>
            </torsional>
          </friction>
          <bounce>
            <restitution_coefficient>0</restitution_coefficient>
            <threshold>1e+06</threshold>
          </bounce>
          <contact>
            <collide_without_contact>0</collide_without_contact>
            <collide_without_contact_bitmask>1</collide_without_contact_bitmask>
            <collide_bitmask>1</collide_bitmask>
            <ode>
              <soft_cfm>0</soft_cfm>
              <soft_erp>0.2</soft_erp>
              <kp>1e+13</kp>
              <kd>1</kd>
              <max_vel>0.01</max_vel>
              <min_depth>0</min_depth>
            </ode>
            <bullet>
              <split_impulse>1</split_impulse>
              <split_impulse_penetration_threshold>-0.01</split_impulse_penetration_threshold>
              <soft_cfm>0</soft_cfm>
              <soft_erp>0.2</soft_erp>
              <kp>1e+13</kp>
              <kd>1</kd>
            </bullet>
          </contact>
        </surface>
      </collision>
      <collision name='head_fixed_joint_lump__screen_collision_1'>
        <laser_retro>0</laser_retro>
        <max_contacts>10</max_contacts>
        <pose frame=''>0.03 0 0.105 1.5708 -0 1.5708</pose>
        <geometry>
          <sphere>
            <radius>0.001</radius>
          </sphere>
        </geometry>
        <surface>
          <friction>
            <ode>
              <mu>1</mu>
              <mu2>1</mu2>
              <fdir1>0 0 0</fdir1>
              <slip1>0</slip1>
              <slip2>0</slip2>
            </ode>
            <torsional>
              <coefficient>1</coefficient>
              <patch_radius>0</patch_radius>
              <surface_radius>0</surface_radius>
              <use_patch_radius>1</use_patch_radius>
              <ode>
                <slip>0</slip>
              </ode>
            </torsional>
          </friction>
          <bounce>
            <restitution_coefficient>0</restitution_coefficient>
            <threshold>1e+06</threshold>
          </bounce>
          <contact>
            <collide_without_contact>0</collide_without_contact>
            <collide_without_contact_bitmask>1</collide_without_contact_bitmask>
            <collide_bitmask>1</collide_bitmask>
            <ode>
              <soft_cfm>0</soft_cfm>
              <soft_erp>0.2</soft_erp>
              <kp>1e+13</kp>
              <kd>1</kd>
              <max_vel>0.01</max_vel>
              <min_depth>0</min_depth>
            </ode>
            <bullet>
              <split_impulse>1</split_impulse>
              <split_impulse_penetration_threshold>-0.01</split_impulse_penetration_threshold>
              <soft_cfm>0</soft_cfm>
              <soft_erp>0.2</soft_erp>
              <kp>1e+13</kp>
              <kd>1</kd>
            </bullet>
          </contact>
        </surface>
      </collision> -->
    <!-- </link> -->
    <link name='right_l0'>
      <pose frame=''>-0 -0 0.08 0 -0 0</pose>
      <inertial>
        <pose frame=''>0.024366 0.010969 0.14363 0 -0 0</pose>
        <mass>5.3213</mass>
        <inertia>
          <ixx>0.053314</ixx>
          <ixy>0.0047093</ixy>
          <ixz>0.011734</ixz>
          <iyy>0.057902</iyy>
          <iyz>0.0080179</iyz>
          <izz>0.023659</izz>
        </inertia>
      </inertial>
      <self_collide>0</self_collide>
      <enable_wind>0</enable_wind>
      <kinematic>0</kinematic>
      <visual name='right_l0_visual'>
        <pose frame=''>0 0 0 0 -0 0</pose>
        <geometry>
          <mesh>
            <scale>1 1 1</scale>
            <uri>model://sawyer/meshes/sawyer_mp3/l0.DAE</uri>
          </mesh>
        </geometry>
        <transparency>0</transparency>
        <cast_shadows>1</cast_shadows>
      </visual>
      <!-- <collision name='right_l0_collision'>
        <laser_retro>0</laser_retro>
        <max_contacts>10</max_contacts>
        <pose frame=''>0.08 0 0.23 0 -0 0</pose>
        <geometry>
          <sphere>
            <radius>0.07</radius>
          </sphere>
        </geometry>
        <surface>
          <friction>
            <ode>
              <mu>1</mu>
              <mu2>1</mu2>
              <fdir1>0 0 0</fdir1>
              <slip1>0</slip1>
              <slip2>0</slip2>
            </ode>
            <torsional>
              <coefficient>1</coefficient>
              <patch_radius>0</patch_radius>
              <surface_radius>0</surface_radius>
              <use_patch_radius>1</use_patch_radius>
              <ode>
                <slip>0</slip>
              </ode>
            </torsional>
          </friction>
          <bounce>
            <restitution_coefficient>0</restitution_coefficient>
            <threshold>1e+06</threshold>
          </bounce>
          <contact>
            <collide_without_contact>0</collide_without_contact>
            <collide_without_contact_bitmask>1</collide_without_contact_bitmask>
            <collide_bitmask>1</collide_bitmask>
            <ode>
              <soft_cfm>0</soft_cfm>
              <soft_erp>0.2</soft_erp>
              <kp>1e+13</kp>
              <kd>1</kd>
              <max_vel>0.01</max_vel>
              <min_depth>0</min_depth>
            </ode>
            <bullet>
              <split_impulse>1</split_impulse>
              <split_impulse_penetration_threshold>-0.01</split_impulse_penetration_threshold>
              <soft_cfm>0</soft_cfm>
              <soft_erp>0.2</soft_erp>
              <kp>1e+13</kp>
              <kd>1</kd>
            </bullet>
          </contact>
        </surface>
      </collision> -->
    </link>
    <link name='right_l1'>
      <pose frame=''>0.081 0.05 0.317 1.56714 1.57079 3.13795</pose>
      <inertial>
        <pose frame=''>-0.003085 -0.026811 0.092521 0 -0 0</pose>
        <mass>4.505</mass>
        <inertia>
          <ixx>0.022398</ixx>
          <ixy>-0.00023986</ixy>
          <ixz>-0.00029362</ixz>
          <iyy>0.014613</iyy>
          <iyz>-0.0060875</iyz>
          <izz>0.017295</izz>
        </inertia>
      </inertial>
      <self_collide>0</self_collide>
      <enable_wind>0</enable_wind>
      <kinematic>0</kinematic>
      <visual name='right_l1_visual'>
        <pose frame=''>0 0 0 0 -0 0</pose>
        <geometry>
          <mesh>
            <scale>1 1 1</scale>
            <uri>model://sawyer/meshes/sawyer_mp3/l1.DAE</uri>
          </mesh>
        </geometry>
        <transparency>0</transparency>
        <cast_shadows>1</cast_shadows>
      </visual>
      <!-- <collision name='right_l1_collision'>
        <laser_retro>0</laser_retro>
        <max_contacts>10</max_contacts>
        <pose frame=''>0 0 0.1225 0 -0 0</pose>
        <geometry>
          <sphere>
            <radius>0.07</radius>
          </sphere>
        </geometry>
        <surface>
          <friction>
            <ode>
              <mu>1</mu>
              <mu2>1</mu2>
              <fdir1>0 0 0</fdir1>
              <slip1>0</slip1>
              <slip2>0</slip2>
            </ode>
            <torsional>
              <coefficient>1</coefficient>
              <patch_radius>0</patch_radius>
              <surface_radius>0</surface_radius>
              <use_patch_radius>1</use_patch_radius>
              <ode>
                <slip>0</slip>
              </ode>
            </torsional>
          </friction>
          <bounce>
            <restitution_coefficient>0</restitution_coefficient>
            <threshold>1e+06</threshold>
          </bounce>
          <contact>
            <collide_without_contact>0</collide_without_contact>
            <collide_without_contact_bitmask>1</collide_without_contact_bitmask>
            <collide_bitmask>1</collide_bitmask>
            <ode>
              <soft_cfm>0</soft_cfm>
              <soft_erp>0.2</soft_erp>
              <kp>1e+13</kp>
              <kd>1</kd>
              <max_vel>0.01</max_vel>
              <min_depth>0</min_depth>
            </ode>
            <bullet>
              <split_impulse>1</split_impulse>
              <split_impulse_penetration_threshold>-0.01</split_impulse_penetration_threshold>
              <soft_cfm>0</soft_cfm>
              <soft_erp>0.2</soft_erp>
              <kp>1e+13</kp>
              <kd>1</kd>
            </bullet>
          </contact>
        </surface>
      </collision>
      <collision name='right_l1_2_collision_1'>
        <laser_retro>0</laser_retro>
        <max_contacts>10</max_contacts>
        <pose frame=''>0 0 0.035 0 -0 0</pose>
        <geometry>
          <cylinder>
            <radius>0.07</radius>
            <length>0.14</length>
          </cylinder>
        </geometry>
        <surface>
          <friction>
            <ode>
              <mu>1</mu>
              <mu2>1</mu2>
              <fdir1>0 0 0</fdir1>
              <slip1>0</slip1>
              <slip2>0</slip2>
            </ode>
            <torsional>
              <coefficient>1</coefficient>
              <patch_radius>0</patch_radius>
              <surface_radius>0</surface_radius>
              <use_patch_radius>1</use_patch_radius>
              <ode>
                <slip>0</slip>
              </ode>
            </torsional>
          </friction>
          <bounce>
            <restitution_coefficient>0</restitution_coefficient>
            <threshold>1e+06</threshold>
          </bounce>
          <contact>
            <collide_without_contact>0</collide_without_contact>
            <collide_without_contact_bitmask>1</collide_without_contact_bitmask>
            <collide_bitmask>1</collide_bitmask>
            <ode>
              <soft_cfm>0</soft_cfm>
              <soft_erp>0.2</soft_erp>
              <kp>1e+13</kp>
              <kd>1</kd>
              <max_vel>0.01</max_vel>
              <min_depth>0</min_depth>
            </ode>
            <bullet>
              <split_impulse>1</split_impulse>
              <split_impulse_penetration_threshold>-0.01</split_impulse_penetration_threshold>
              <soft_cfm>0</soft_cfm>
              <soft_erp>0.2</soft_erp>
              <kp>1e+13</kp>
              <kd>1</kd>
            </bullet>
          </contact>
        </surface>
      </collision> -->
    </link>
    <link name='right_l2'>
      <pose frame=''>0.221 0.1925 0.317 3.14159 1.57079 3.14159</pose>
      <inertial>
        <pose frame=''>-0.00016 -0.014967 0.13582 0 -0 0</pose>
        <mass>1.745</mass>
        <inertia>
          <ixx>0.025506</ixx>
          <ixy>4.4101e-06</ixy>
          <ixz>1.4955e-05</ixz>
          <iyy>0.0253</iyy>
          <iyz>-0.0033204</iyz>
          <izz>0.0034179</izz>
        </inertia>
      </inertial>
      <self_collide>0</self_collide>
      <enable_wind>0</enable_wind>
      <kinematic>0</kinematic>
      <visual name='right_l2_visual'>
        <pose frame=''>0 0 0 0 -0 0</pose>
        <geometry>
          <mesh>
            <scale>1 1 1</scale>
            <uri>model://sawyer/meshes/sawyer_pv/l2.DAE</uri>
          </mesh>
        </geometry>
        <transparency>0</transparency>
        <cast_shadows>1</cast_shadows>
      </visual>
      <!-- <collision name='right_l2_collision'>
        <laser_retro>0</laser_retro>
        <max_contacts>10</max_contacts>
        <pose frame=''>0 0 0.08 0 -0 0</pose>
        <geometry>
          <cylinder>
            <radius>0.06</radius>
            <length>0.34</length>
          </cylinder>
        </geometry>
        <surface>
          <friction>
            <ode>
              <mu>1</mu>
              <mu2>1</mu2>
              <fdir1>0 0 0</fdir1>
              <slip1>0</slip1>
              <slip2>0</slip2>
            </ode>
            <torsional>
              <coefficient>1</coefficient>
              <patch_radius>0</patch_radius>
              <surface_radius>0</surface_radius>
              <use_patch_radius>1</use_patch_radius>
              <ode>
                <slip>0</slip>
              </ode>
            </torsional>
          </friction>
          <bounce>
            <restitution_coefficient>0</restitution_coefficient>
            <threshold>1e+06</threshold>
          </bounce>
          <contact>
            <collide_without_contact>0</collide_without_contact>
            <collide_without_contact_bitmask>1</collide_without_contact_bitmask>
            <collide_bitmask>1</collide_bitmask>
            <ode>
              <soft_cfm>0</soft_cfm>
              <soft_erp>0.2</soft_erp>
              <kp>1e+13</kp>
              <kd>1</kd>
              <max_vel>0.01</max_vel>
              <min_depth>0</min_depth>
            </ode>
            <bullet>
              <split_impulse>1</split_impulse>
              <split_impulse_penetration_threshold>-0.01</split_impulse_penetration_threshold>
              <soft_cfm>0</soft_cfm>
              <soft_erp>0.2</soft_erp>
              <kp>1e+13</kp>
              <kd>1</kd>
            </bullet>
          </contact>
        </surface>
      </collision>
      <collision name='right_l2_2_collision_1'>
        <laser_retro>0</laser_retro>
        <max_contacts>10</max_contacts>
        <pose frame=''>0 0 0.26 0 -0 0</pose>
        <geometry>
          <sphere>
            <radius>0.06</radius>
          </sphere>
        </geometry>
        <surface>
          <friction>
            <ode>
              <mu>1</mu>
              <mu2>1</mu2>
              <fdir1>0 0 0</fdir1>
              <slip1>0</slip1>
              <slip2>0</slip2>
            </ode>
            <torsional>
              <coefficient>1</coefficient>
              <patch_radius>0</patch_radius>
              <surface_radius>0</surface_radius>
              <use_patch_radius>1</use_patch_radius>
              <ode>
                <slip>0</slip>
              </ode>
            </torsional>
          </friction>
          <bounce>
            <restitution_coefficient>0</restitution_coefficient>
            <threshold>1e+06</threshold>
          </bounce>
          <contact>
            <collide_without_contact>0</collide_without_contact>
            <collide_without_contact_bitmask>1</collide_without_contact_bitmask>
            <collide_bitmask>1</collide_bitmask>
            <ode>
              <soft_cfm>0</soft_cfm>
              <soft_erp>0.2</soft_erp>
              <kp>1e+13</kp>
              <kd>1</kd>
              <max_vel>0.01</max_vel>
              <min_depth>0</min_depth>
            </ode>
            <bullet>
              <split_impulse>1</split_impulse>
              <split_impulse_penetration_threshold>-0.01</split_impulse_penetration_threshold>
              <soft_cfm>0</soft_cfm>
              <soft_erp>0.2</soft_erp>
              <kp>1e+13</kp>
              <kd>1</kd>
            </bullet>
          </contact>
        </surface>
      </collision> -->
    </link>
    <link name='right_l3'>
      <pose frame=''>0.481 0.1505 0.317 1.56714 1.57079 3.13795</pose>
      <inertial>
        <pose frame=''>-0.004814 -0.0281 -0.084154 0 -0 0</pose>
        <mass>2.5097</mass>
        <inertia>
          <ixx>0.01016</ixx>
          <ixy>-9.7452e-06</ixy>
          <ixz>0.00026624</ixz>
          <iyy>0.0065685</iyy>
          <iyz>0.0030316</iyz>
          <izz>0.0069078</izz>
        </inertia>
      </inertial>
      <self_collide>0</self_collide>
      <enable_wind>0</enable_wind>
      <kinematic>0</kinematic>
      <visual name='right_l3_visual'>
        <pose frame=''>0 0 0 0 -0 0</pose>
        <geometry>
          <mesh>
            <scale>1 1 1</scale>
            <uri>model://sawyer/meshes/sawyer_pv/l3.DAE</uri>
          </mesh>
        </geometry>
        <transparency>0</transparency>
        <cast_shadows>1</cast_shadows>
      </visual>
      <!-- <collision name='right_l3_collision'>
        <laser_retro>0</laser_retro>
        <max_contacts>10</max_contacts>
        <pose frame=''>0 -0.01 -0.12 0 -0 0</pose>
        <geometry>
          <sphere>
            <radius>0.06</radius>
          </sphere>
        </geometry>
        <surface>
          <friction>
            <ode>
              <mu>1</mu>
              <mu2>1</mu2>
              <fdir1>0 0 0</fdir1>
              <slip1>0</slip1>
              <slip2>0</slip2>
            </ode>
            <torsional>
              <coefficient>1</coefficient>
              <patch_radius>0</patch_radius>
              <surface_radius>0</surface_radius>
              <use_patch_radius>1</use_patch_radius>
              <ode>
                <slip>0</slip>
              </ode>
            </torsional>
          </friction>
          <bounce>
            <restitution_coefficient>0</restitution_coefficient>
            <threshold>1e+06</threshold>
          </bounce>
          <contact>
            <collide_without_contact>0</collide_without_contact>
            <collide_without_contact_bitmask>1</collide_without_contact_bitmask>
            <collide_bitmask>1</collide_bitmask>
            <ode>
              <soft_cfm>0</soft_cfm>
              <soft_erp>0.2</soft_erp>
              <kp>1e+13</kp>
              <kd>1</kd>
              <max_vel>0.01</max_vel>
              <min_depth>0</min_depth>
            </ode>
            <bullet>
              <split_impulse>1</split_impulse>
              <split_impulse_penetration_threshold>-0.01</split_impulse_penetration_threshold>
              <soft_cfm>0</soft_cfm>
              <soft_erp>0.2</soft_erp>
              <kp>1e+13</kp>
              <kd>1</kd>
            </bullet>
          </contact>
        </surface>
      </collision> -->
    </link>
    <link name='right_l4'>
      <pose frame=''>0.606 0.024 0.317 3.14159 1.57079 3.14159</pose>
      <inertial>
        <pose frame=''>-0.001884 0.0069 0.1341 0 -0 0</pose>
        <mass>1.1136</mass>
        <inertia>
          <ixx>0.013557</ixx>
          <ixy>1.8109e-05</ixy>
          <ixz>0.00013523</ixz>
          <iyy>0.013555</iyy>
          <iyz>0.0010561</iyz>
          <izz>0.0013658</izz>
        </inertia>
      </inertial>
      <self_collide>0</self_collide>
      <enable_wind>0</enable_wind>
      <kinematic>0</kinematic>
      <visual name='right_l4_visual'>
        <pose frame=''>0 0 0 0 -0 0</pose>
        <geometry>
          <mesh>
            <scale>1 1 1</scale>
            <uri>model://sawyer/meshes/sawyer_pv/l4.DAE</uri>
          </mesh>
        </geometry>
        <transparency>0</transparency>
        <cast_shadows>1</cast_shadows>
      </visual>
      <!-- <collision name='right_l4_collision'>
        <laser_retro>0</laser_retro>
        <max_contacts>10</max_contacts>
        <pose frame=''>0 0 0.11 0 -0 0</pose>
        <geometry>
          <cylinder>
            <radius>0.045</radius>
            <length>0.3</length>
          </cylinder>
        </geometry>
        <surface>
          <friction>
            <ode>
              <mu>1</mu>
              <mu2>1</mu2>
              <fdir1>0 0 0</fdir1>
              <slip1>0</slip1>
              <slip2>0</slip2>
            </ode>
            <torsional>
              <coefficient>1</coefficient>
              <patch_radius>0</patch_radius>
              <surface_radius>0</surface_radius>
              <use_patch_radius>1</use_patch_radius>
              <ode>
                <slip>0</slip>
              </ode>
            </torsional>
          </friction>
          <bounce>
            <restitution_coefficient>0</restitution_coefficient>
            <threshold>1e+06</threshold>
          </bounce>
          <contact>
            <collide_without_contact>0</collide_without_contact>
            <collide_without_contact_bitmask>1</collide_without_contact_bitmask>
            <collide_bitmask>1</collide_bitmask>
            <ode>
              <soft_cfm>0</soft_cfm>
              <soft_erp>0.2</soft_erp>
              <kp>1e+13</kp>
              <kd>1</kd>
              <max_vel>0.01</max_vel>
              <min_depth>0</min_depth>
            </ode>
            <bullet>
              <split_impulse>1</split_impulse>
              <split_impulse_penetration_threshold>-0.01</split_impulse_penetration_threshold>
              <soft_cfm>0</soft_cfm>
              <soft_erp>0.2</soft_erp>
              <kp>1e+13</kp>
              <kd>1</kd>
            </bullet>
          </contact>
        </surface>
      </collision>
      <collision name='right_l4_2_collision_1'>
        <laser_retro>0</laser_retro>
        <max_contacts>10</max_contacts>
        <pose frame=''>0 0.01 0.26 0 -0 0</pose>
        <geometry>
          <sphere>
            <radius>0.06</radius>
          </sphere>
        </geometry>
        <surface>
          <friction>
            <ode>
              <mu>1</mu>
              <mu2>1</mu2>
              <fdir1>0 0 0</fdir1>
              <slip1>0</slip1>
              <slip2>0</slip2>
            </ode>
            <torsional>
              <coefficient>1</coefficient>
              <patch_radius>0</patch_radius>
              <surface_radius>0</surface_radius>
              <use_patch_radius>1</use_patch_radius>
              <ode>
                <slip>0</slip>
              </ode>
            </torsional>
          </friction>
          <bounce>
            <restitution_coefficient>0</restitution_coefficient>
            <threshold>1e+06</threshold>
          </bounce>
          <contact>
            <collide_without_contact>0</collide_without_contact>
            <collide_without_contact_bitmask>1</collide_without_contact_bitmask>
            <collide_bitmask>1</collide_bitmask>
            <ode>
              <soft_cfm>0</soft_cfm>
              <soft_erp>0.2</soft_erp>
              <kp>1e+13</kp>
              <kd>1</kd>
              <max_vel>0.01</max_vel>
              <min_depth>0</min_depth>
            </ode>
            <bullet>
              <split_impulse>1</split_impulse>
              <split_impulse_penetration_threshold>-0.01</split_impulse_penetration_threshold>
              <soft_cfm>0</soft_cfm>
              <soft_erp>0.2</soft_erp>
              <kp>1e+13</kp>
              <kd>1</kd>
            </bullet>
          </contact>
        </surface>
      </collision> -->
    </link>
    <link name='right_l5'>
      <pose frame=''>0.881 0.055 0.317 1.56714 1.57079 3.13795</pose>
      <inertial>
        <pose frame=''>0.006113 -0.023697 0.076416 0 -0 0</pose>
        <mass>1.5625</mass>
        <inertia>
          <ixx>0.0047328</ixx>
          <ixy>0.00011526</ixy>
          <ixz>4.6269e-05</ixz>
          <iyy>0.0029676</iyy>
          <iyz>-0.0011557</iyz>
          <izz>0.0031762</izz>
        </inertia>
      </inertial>
      <gravity>1</gravity>
      <velocity_decay/>
      <sensor name='right_hand_camera' type='camera'>
        <update_rate>10</update_rate>
        <camera name='right_hand_camera'>
          <horizontal_fov>1.09929</horizontal_fov>
          <image>
            <width>752</width>
            <height>480</height>
            <format>L8</format>
          </image>
          <clip>
            <near>0.02</near>
            <far>10</far>
          </clip>
        </camera>
        <pose frame=''>0.039552 -0.033 0.0695 1.5708 -0 0</pose>
      </sensor>
      <self_collide>0</self_collide>
      <enable_wind>0</enable_wind>
      <kinematic>0</kinematic>
      <visual name='right_l5_visual'>
        <pose frame=''>0 0 0 0 -0 0</pose>
        <geometry>
          <mesh>
            <scale>1 1 1</scale>
            <uri>model://sawyer/meshes/sawyer_pv/l5.DAE</uri>
          </mesh>
        </geometry>
        <material>
            
            <ambient>0.1 0.1 0.1 1</ambient>
            <diffuse>0.286275 0.286275 0.286275 1</diffuse>
            <specular>0.286275 0.286275 0.286275 1</specular>
            <emissive>0 0 0 1</emissive>
          </material>
        <transparency>0</transparency>
        <cast_shadows>1</cast_shadows>
      </visual>
      <!-- <collision name='right_l5_collision'>
        <laser_retro>0</laser_retro>
        <max_contacts>10</max_contacts>
        <pose frame=''>0 0 0.1 0 -0 0</pose>
        <geometry>
          <sphere>
            <radius>0.06</radius>
          </sphere>
        </geometry>
        <surface>
          <friction>
            <ode>
              <mu>1</mu>
              <mu2>1</mu2>
              <fdir1>0 0 0</fdir1>
              <slip1>0</slip1>
              <slip2>0</slip2>
            </ode>
            <torsional>
              <coefficient>1</coefficient>
              <patch_radius>0</patch_radius>
              <surface_radius>0</surface_radius>
              <use_patch_radius>1</use_patch_radius>
              <ode>
                <slip>0</slip>
              </ode>
            </torsional>
          </friction>
          <bounce>
            <restitution_coefficient>0</restitution_coefficient>
            <threshold>1e+06</threshold>
          </bounce>
          <contact>
            <collide_without_contact>0</collide_without_contact>
            <collide_without_contact_bitmask>1</collide_without_contact_bitmask>
            <collide_bitmask>1</collide_bitmask>
            <ode>
              <soft_cfm>0</soft_cfm>
              <soft_erp>0.2</soft_erp>
              <kp>1e+13</kp>
              <kd>1</kd>
              <max_vel>0.01</max_vel>
              <min_depth>0</min_depth>
            </ode>
            <bullet>
              <split_impulse>1</split_impulse>
              <split_impulse_penetration_threshold>-0.01</split_impulse_penetration_threshold>
              <soft_cfm>0</soft_cfm>
              <soft_erp>0.2</soft_erp>
              <kp>1e+13</kp>
              <kd>1</kd>
            </bullet>
          </contact>
        </surface>
      </collision> -->
    </link>
    <link name='right_l6'>
      <pose frame=''>0.991 0.1603 0.317 1.57084 -1.39627 1.57075</pose>
      <inertial>
        <pose frame=''>-0.001007 0.005118 0.029535 0 -0 0</pose>
        <mass>0.809204</mass>
        <inertia>
          <ixx>0.0110546</ixx>
          <ixy>-0.0100033</ixy>
          <ixz>-0.01001</ixz>
          <iyy>0.0110533</iyy>
          <iyz>0.0100554</iyz>
          <izz>0.0105897</izz>
        </inertia>
      </inertial>
      <gravity>1</gravity>
      <velocity_decay/>
      <self_collide>0</self_collide>
      <enable_wind>0</enable_wind>
      <kinematic>0</kinematic>
      <visual name='right_l6_fixed_joint_visual_1'>
        <!-- <pose frame=''>0 0 0.0213 0 -0 1.5708</pose> -->
        <geometry>
          <mesh>
            <scale>1 1 1</scale>
            <!-- <uri>model://sawyer/meshes/connector_plate/connector_plate.STL</uri> -->
            <uri>model://sawyer/meshes/sawyer_pv/l6.DAE</uri>
          </mesh>
        </geometry>
        <material>
          <script>
            <name>Gazebo/FlatBlack</name>
            <uri>file://media/materials/scripts/gazebo.material</uri>
          </script>
          <emissive>0 0 0 1</emissive>
        </material>
        <transparency>0</transparency>
        <cast_shadows>1</cast_shadows>
      </visual>
      <visual name='right_l6_fixed_joint_lump__right_connector_plate_base_visual_1'>
        <!-- <pose frame=''>0 0 0.0213 0 -0 1.5708</pose> -->
        <geometry>
          <mesh>
            <scale>1 1 1</scale>
            <uri>model://sawyer/meshes/connector_plate/connector_plate.STL</uri>
            <!-- <uri>model://sawyer/meshes/sawyer_pv/l6.DAE</uri> -->
          </mesh>
        </geometry>
        <material>
          <script>
            <name>Gazebo/FlatBlack</name>
            <uri>file://media/materials/scripts/gazebo.material</uri>
          </script>
          <emissive>0 0 0 1</emissive>
        </material>
        <transparency>0</transparency>
        <cast_shadows>1</cast_shadows>
      </visual>
      <!-- <collision name='right_l6_collision'>
        <laser_retro>0</laser_retro>
        <max_contacts>10</max_contacts>
        <pose frame=''>0 0.015 -0.01 0 -0 0</pose>
        <geometry>
          <cylinder>
            <radius>0.055</radius>
            <length>0.05</length>
          </cylinder>
        </geometry>
        <surface>
          <friction>
            <ode>
              <mu>1</mu>
              <mu2>1</mu2>
              <fdir1>0 0 0</fdir1>
              <slip1>0</slip1>
              <slip2>0</slip2>
            </ode>
            <torsional>
              <coefficient>1</coefficient>
              <patch_radius>0</patch_radius>
              <surface_radius>0</surface_radius>
              <use_patch_radius>1</use_patch_radius>
              <ode>
                <slip>0</slip>
              </ode>
            </torsional>
          </friction>
          <bounce>
            <restitution_coefficient>0</restitution_coefficient>
            <threshold>1e+06</threshold>
          </bounce>
          <contact>
            <collide_without_contact>0</collide_without_contact>
            <collide_without_contact_bitmask>1</collide_without_contact_bitmask>
            <collide_bitmask>1</collide_bitmask>
            <ode>
              <soft_cfm>0</soft_cfm>
              <soft_erp>0.2</soft_erp>
              <kp>1e+13</kp>
              <kd>1</kd>
              <max_vel>0.01</max_vel>
              <min_depth>0</min_depth>
            </ode>
            <bullet>
              <split_impulse>1</split_impulse>
              <split_impulse_penetration_threshold>-0.01</split_impulse_penetration_threshold>
              <soft_cfm>0</soft_cfm>
              <soft_erp>0.2</soft_erp>
              <kp>1e+13</kp>
              <kd>1</kd>
            </bullet>
          </contact>
        </surface>
      </collision> -->
    </link>
    <model name='gripper'>
      <link name='body'>
        <self_collide>0</self_collide>
        <enable_wind>0</enable_wind>
        <kinematic>0</kinematic>
        <pose>0 0 0 0 -0 0</pose>
        <gravity>1</gravity>
        <inertial>
          <mass>0.05</mass>
          <pose>0 0 0 0 -0 0</pose>
          <inertia>
            <ixx>1</ixx>
            <ixy>0</ixy>
            <ixz>0</ixz>
            <iyy>1</iyy>
            <iyz>0</iyz>
            <izz>1</izz>
          </inertia>
        </inertial>
        <visual name='visual'>
          <geometry>
            <mesh>
              <uri>model://gripper/model.dae</uri>
              <scale>1 1 1</scale>
            </mesh>
          </geometry>
          <material>
            <script>
              <uri>__default__</uri>
              <name>__default__</name>
            </script>
          </material>
          <pose>0 0 0 0 -0 0</pose>
          <transparency>0</transparency>
          <cast_shadows>1</cast_shadows>
        </visual>

        <collision name="contact_sensor_collision">
          <pose>0 0 -0.05 0 0 0</pose>
          <geometry>
            <cylinder>
              <radius>0.01</radius>
              <length>0.10</length>
            </cylinder>
          </geometry>
          <surface>
            <contact>
              <collide_without_contact>true</collide_without_contact>
            </contact>
          </surface>
        </collision>

        <sensor name="logical_camera" type="logical_camera">
          <pose>0. 0 0 0 1.57 3.14159</pose>
          <logical_camera>
            <near>0.01</near>
            <far>0.115</far>
            <aspect_ratio>1</aspect_ratio>
            <horizontal_fov>1</horizontal_fov>
          </logical_camera>
          <always_on>1</always_on>
          <update_rate>100</update_rate>
          <visualize>false</visualize>
        </sensor>
        <sensor name="contact_sensor" type="contact">
          <contact>
          <collision>contact_sensor_collision</collision>          
          </contact>
          <always_on>true</always_on>
        </sensor>
      </link>
      <static>0</static>
      <allow_auto_disable>1</allow_auto_disable>
      <!--<pose>-0.8249 -0.230516 0.06 1.60487 -0 3.1415926</pose>-->
      <pose frame=''>1.01475 0.160336 0.319807 -3.14159 -1.55801 3.14159</pose>
    </model>
    <!-- <joint name='head_pan' type='revolute'>
      <parent>right_l0</parent>
      <child>head</child>
      <pose frame=''>0 0 0 0 -0 0</pose>
      <axis>
        <xyz>0 0 1</xyz>
        <use_parent_model_frame>1</use_parent_model_frame>
        <limit>
          <lower>-5.0952</lower>
          <upper>0.9064</upper>
          <effort>8</effort>
          <velocity>1.8</velocity>
        </limit>
        <dynamics>
          <spring_reference>0</spring_reference>
          <spring_stiffness>0</spring_stiffness>
          <damping>1</damping>
          <friction>0.5</friction>
        </dynamics>
      </axis>
      <physics>
        <ode>
          <limit>
            <cfm>0</cfm>
            <erp>0.2</erp>
          </limit>
          <suspension>
            <cfm>0</cfm>
            <erp>0.2</erp>
          </suspension>
        </ode>
      </physics>
    </joint> -->
    <joint name='right_j0' type='revolute'>
      <parent>base</parent>
      <child>right_l0</child>
      <pose frame=''>0 0 0 0 -0 0</pose>
      <axis>
        <xyz>0 0 1</xyz>
        <use_parent_model_frame>1</use_parent_model_frame>
        <limit>
          <lower>-3.0503</lower>
          <upper>3.0503</upper>
          <effort>80</effort>
          <velocity>1.74</velocity>
        </limit>
        <dynamics>
          <spring_reference>0</spring_reference>
          <spring_stiffness>0</spring_stiffness>
          <damping>10</damping>
          <friction>5</friction>
        </dynamics>
      </axis>
      <physics>
        <ode>
          <limit>
            <cfm>0</cfm>
            <erp>0.2</erp>
          </limit>
          <suspension>
            <cfm>0</cfm>
            <erp>0.2</erp>
          </suspension>
        </ode>
      </physics>
    </joint>
    <joint name='right_j1' type='revolute'>
      <parent>right_l0</parent>
      <child>right_l1</child>
      <pose frame=''>0 0 0 0 -0 0</pose>
      <axis>
        <xyz>0 1 -0</xyz>
        <use_parent_model_frame>1</use_parent_model_frame>
        <limit>
          <lower>-3.8095</lower>
          <upper>2.2736</upper>
          <effort>80</effort>
          <velocity>1.328</velocity>
        </limit>
        <dynamics>
          <spring_reference>0</spring_reference>
          <spring_stiffness>0</spring_stiffness>
          <damping>5</damping>
          <friction>2</friction>
        </dynamics>
      </axis>
      <physics>
        <ode>
          <limit>
            <cfm>0</cfm>
            <erp>0.2</erp>
          </limit>
          <suspension>
            <cfm>0</cfm>
            <erp>0.2</erp>
          </suspension>
        </ode>
      </physics>
    </joint>
    <joint name='right_j2' type='revolute'>
      <parent>right_l1</parent>
      <child>right_l2</child>
      <pose frame=''>0 0 0 0 -0 0</pose>
      <axis>
        <xyz>1 0 0</xyz>
        <use_parent_model_frame>1</use_parent_model_frame>
        <limit>
          <lower>-3.0426</lower>
          <upper>3.0426</upper>
          <effort>40</effort>
          <velocity>1.957</velocity>
        </limit>
        <dynamics>
          <spring_reference>0</spring_reference>
          <spring_stiffness>0</spring_stiffness>
          <damping>5</damping>
          <friction>2</friction>
        </dynamics>
      </axis>
      <physics>
        <ode>
          <limit>
            <cfm>0</cfm>
            <erp>0.2</erp>
          </limit>
          <suspension>
            <cfm>0</cfm>
            <erp>0.2</erp>
          </suspension>
        </ode>
      </physics>
    </joint>
    <joint name='right_j3' type='revolute'>
      <parent>right_l2</parent>
      <child>right_l3</child>
      <pose frame=''>0 0 0 0 -0 0</pose>
      <axis>
        <xyz>0 1 -0</xyz>
        <use_parent_model_frame>1</use_parent_model_frame>
        <limit>
          <lower>-3.0439</lower>
          <upper>3.0439</upper>
          <effort>40</effort>
          <velocity>1.957</velocity>
        </limit>
        <dynamics>
          <spring_reference>0</spring_reference>
          <spring_stiffness>0</spring_stiffness>
          <damping>1</damping>
          <friction>0.5</friction>
        </dynamics>
      </axis>
      <physics>
        <ode>
          <limit>
            <cfm>0</cfm>
            <erp>0.2</erp>
          </limit>
          <suspension>
            <cfm>0</cfm>
            <erp>0.2</erp>
          </suspension>
        </ode>
      </physics>
    </joint>
    <joint name='right_j4' type='revolute'>
      <parent>right_l3</parent>
      <child>right_l4</child>
      <pose frame=''>0 0 0 0 -0 0</pose>
      <axis>
        <xyz>1 0 0</xyz>
        <use_parent_model_frame>1</use_parent_model_frame>
        <limit>
          <lower>-2.9761</lower>
          <upper>2.9761</upper>
          <effort>9</effort>
          <velocity>3.485</velocity>
        </limit>
        <dynamics>
          <spring_reference>0</spring_reference>
          <spring_stiffness>0</spring_stiffness>
          <damping>2</damping>
          <friction>1</friction>
        </dynamics>
      </axis>
      <physics>
        <ode>
          <limit>
            <cfm>0</cfm>
            <erp>0.2</erp>
          </limit>
          <suspension>
            <cfm>0</cfm>
            <erp>0.2</erp>
          </suspension>
        </ode>
      </physics>
    </joint>
    <joint name='right_j5' type='revolute'>
      <parent>right_l4</parent>
      <child>right_l5</child>
      <pose frame=''>0 0 0 0 -0 0</pose>
      <axis>
        <xyz>0 1 -0</xyz>
        <use_parent_model_frame>1</use_parent_model_frame>
        <limit>
          <lower>-2.9761</lower>
          <upper>2.9761</upper>
          <effort>9</effort>
          <velocity>3.485</velocity>
        </limit>
        <dynamics>
          <spring_reference>0</spring_reference>
          <spring_stiffness>0</spring_stiffness>
          <damping>1</damping>
          <friction>0.5</friction>
        </dynamics>
      </axis>
      <physics>
        <ode>
          <limit>
            <cfm>0</cfm>
            <erp>0.2</erp>
          </limit>
          <suspension>
            <cfm>0</cfm>
            <erp>0.2</erp>
          </suspension>
        </ode>
      </physics>
    </joint>
    <joint name='right_j6' type='revolute'>
      <parent>right_l5</parent>
      <child>right_l6</child>
      <pose frame=''>0 0 0 0 -0 0</pose>
      <axis>
        <xyz>1 -0 -7e-06</xyz>
        <use_parent_model_frame>1</use_parent_model_frame>
        <limit>
          <lower>-3.14</lower>
          <upper>3.14</upper>
          <effort>9</effort>
          <velocity>4.545</velocity>
        </limit>
        <dynamics>
          <spring_reference>0</spring_reference>
          <spring_stiffness>0</spring_stiffness>
          <damping>1</damping>
          <friction>0.5</friction>
        </dynamics>
      </axis>
      <physics>
        <ode>
          <limit>
            <cfm>0</cfm>
            <erp>0.2</erp>
          </limit>
          <suspension>
            <cfm>0</cfm>
            <erp>0.2</erp>
          </suspension>
        </ode>
      </physics>
    </joint>
    <joint name='right_l6_JOINT_0' type='fixed'>
      <parent>right_l6</parent>
      <child>gripper::body</child>
      <pose frame=''>0 0 0 0 -0 0</pose>
      <physics>
        <ode>
          <limit>
            <cfm>0</cfm>
            <erp>0.2</erp>
          </limit>
          <suspension>
            <cfm>0</cfm>
            <erp>0.2</erp>
          </suspension>
        </ode>
      </physics>
    </joint>

    <joint name='fix to ground' type='fixed'>
      <parent>world</parent>
      <child>base</child>
    </joint>

    <static>0</static>
    <allow_auto_disable>1</allow_auto_disable>
    <gazebo_robotraconteur_server_plugin_model>      
      <kinematic_joint_controller>
        <joint name="right_j0">
          <initial_position>0</initial_position>
        </joint>
        <joint name="right_j1">
          <initial_position>-1.396263</initial_position>
        </joint>
        <joint name="right_j2">
          <initial_position>0</initial_position>
        </joint>
        <joint name="right_j3">
          <initial_position>2.094395</initial_position>
        </joint>
        <joint name="right_j4">
          <initial_position>0</initial_position>
        </joint>
        <joint name="right_j5">
          <initial_position>0.872664</initial_position>
        </joint>
        <joint name="right_j6">
          <initial_position>0</initial_position>
        </joint>
      </kinematic_joint_controller>      
    </gazebo_robotraconteur_server_plugin_model>
  </model>
</sdf>
