<?xml version="1.0" encoding="utf-8"?>
<!-- =================================================================================== -->
<!-- |    This document was autogenerated by xacro from ur5_robot.urdf.xacro           | -->
<!-- |    EDITING THIS FILE BY HAND IS NOT RECOMMENDED                                 | -->
<!-- =================================================================================== -->
<robot name="combined">
  <!--robots pose-->
  <link name="world"/>


  <joint name="ur5e1_pose" type="fixed">
    <parent link="world"/>
    <child link="ur5e1__link_0"/>
    <origin rpy="0.0 0.0 0.0" xyz="0 1.2 0.0"/><!--abb pedestal-->
  </joint>
  <joint name="ur5e2_pose" type="fixed">
    <parent link="world"/>
    <child link="ur5e2__link_0"/>
    <origin rpy="0.0 0.0 0.0" xyz="0 0.0 0.0"/><!--abb pedestal-->
  </joint>



<!-- robot urdf start here -->

  <!--ur5e1 part-->
  <joint name="ur5e1__elbow_joint" type="revolute">
    <parent link="ur5e1__upper_arm_link"/>
    <child link="ur5e1__forearm_link"/>
    <origin xyz="-0.425  0     0" rpy="0 0 0"/>
    <axis xyz="0 0 1"/>
    <limit lower="-3.14159" upper="3.14159" effort="150.0" velocity="3.14159"/>
  </joint>
  <joint name="ur5e1__link_0_JOINT_1" type="fixed">
    <parent link="ur5e1__link_0"/>
    <child link="ur5e1__base_link"/>
    <origin xyz="0 0 0" rpy="0      0      3.14159"/>
    <axis xyz="0 0 0"/>
    <limit lower="0" upper="0" effort="0" velocity="0"/>
  </joint>
  <joint name="ur5e1__shoulder_lift_joint" type="revolute">
    <parent link="ur5e1__shoulder_link"/>
    <child link="ur5e1__upper_arm_link"/>
    <origin xyz="0 0 0" rpy="1.5708 0     0"/>
    <axis xyz="0 0 1"/>
    <limit lower="-6.28319" upper="6.28319" effort="150.0" velocity="3.14159"/>
  </joint>
  <joint name="ur5e1__shoulder_pan_joint" type="revolute">
    <parent link="ur5e1__base_link"/>
    <child link="ur5e1__shoulder_link"/>
    <origin xyz="0     0     0.1625" rpy="0       0      -3.14159"/>
    <axis xyz="0 0 1"/>
    <limit lower="-6.28319" upper="6.28319" effort="150.0" velocity="3.14159"/>
  </joint>
  <joint name="ur5e1__wrist_1_joint" type="revolute">
    <parent link="ur5e1__forearm_link"/>
    <child link="ur5e1__wrist_1_link"/>
    <origin xyz="-0.3922   0       0.13329" rpy="0 0 0"/>
    <axis xyz="0 0 1"/>
    <limit lower="-6.28319" upper="6.28319" effort="28.0" velocity="3.14159"/>
  </joint>
  <joint name="ur5e1__wrist_2_joint" type="revolute">
    <parent link="ur5e1__wrist_1_link"/>
    <child link="ur5e1__wrist_2_link"/>
    <origin xyz="0     -0.0997  0" rpy="1.57079 0      0"/>
    <axis xyz="0 0 1"/>
    <limit lower="-6.28319" upper="6.28319" effort="28.0" velocity="3.14159"/>
  </joint>
  <joint name="ur5e1__wrist_3_joint" type="revolute">
    <parent link="ur5e1__wrist_2_link"/>
    <child link="ur5e1__wrist_3_link"/>
    <origin xyz="0     0.0996 0" rpy="-1.57079  0       0"/>
    <axis xyz="0 0 1"/>
    <limit lower="-6.28319" upper="6.28319" effort="28.0" velocity="3.14159"/>
  </joint>
  <link name="ur5e1__base_link">
    <inertial>
      <mass value="4"/>
      <origin xyz="0 0 0" rpy="0 0 0"/>
      <inertia ixx="0.00443333" ixy="0" ixz="0" iyy="0.00443333" iyz="0" izz="0.0072"/>
    </inertial>
    <collision name="ur5e1__base_link_inertia_collision">
      <origin xyz="0 0 0" rpy="0       0      -3.14159"/>
      <geometry>
        <mesh filename="model://ur5e/meshes/collision/base.stl" scale="1 1 1"/>
      </geometry>
    </collision>
    <visual name="ur5e1__base_link_inertia_visual">
      <origin xyz="0 0 0" rpy="0       0      -3.14159"/>
      <geometry>
        <mesh filename="model://ur5e/meshes/visual/base.dae" scale="1 1 1"/>
      </geometry>
    </visual>
  </link>
  <link name="ur5e1__forearm_link">
    <inertial>
      <mass value="2.275"/>
      <origin xyz="-0.1961  0      0.007" rpy="3.14159 1.57079 3.14159"/>
      <inertia ixx="0.0312094" ixy="0" ixz="0" iyy="0.0312094" iyz="0" izz="0.004095"/>
    </inertial>
    <collision name="ur5e1__forearm_link_collision">
      <origin xyz="0    0    0.007" rpy="1.5708  0     -1.5708"/>
      <geometry>
        <mesh filename="model://ur5e/meshes/collision/forearm.stl" scale="1 1 1"/>
      </geometry>
    </collision>
    <visual name="ur5e1__forearm_link_visual">
      <origin xyz="0    0    0.007" rpy="1.5708  0     -1.5708"/>
      <geometry>
        <mesh filename="model://ur5e/meshes/visual/forearm.stl" scale="1 1 1"/>
      </geometry>
    </visual>
  </link>
  <link name="ur5e1__link_0">
    <inertial>
      <mass value="1"/>
      <origin xyz="0 0 0" rpy="0 0 0"/>
      <inertia ixx="0.145833" ixy="0" ixz="0" iyy="0.145833" iyz="0" izz="0.125"/>
    </inertial>
    <visual name="ur5e1__visual">
      <origin xyz="0   0  -0.5" rpy="-2.0e-05  1.4e-04  0.0e+00"/>
      <geometry>
        <cylinder radius="0.15" length="1"/>
      </geometry>
    </visual>
  </link>
  <link name="ur5e1__shoulder_link">
    <inertial>
      <mass value="3.7"/>
      <origin xyz="0 0 0" rpy="0 0 0"/>
      <inertia ixx="0.0102675" ixy="0" ixz="0" iyy="0.0102675" iyz="0" izz="0.00666"/>
    </inertial>
    <collision name="ur5e1__shoulder_link_collision">
      <origin xyz="0 0 0" rpy="0      0      3.14159"/>
      <geometry>
        <mesh filename="model://ur5e/meshes/collision/shoulder.stl" scale="1 1 1"/>
      </geometry>
    </collision>
    <visual name="ur5e1__shoulder_link_visual">
      <origin xyz="0 0 0" rpy="0      0      3.14159"/>
      <geometry>
        <mesh filename="model://ur5e/meshes/visual/shoulder.dae" scale="1 1 1"/>
      </geometry>
    </visual>
  </link>
  <link name="ur5e1__upper_arm_link">
    <inertial>
      <mass value="8.393"/>
      <origin xyz="-0.2125  0      0.138" rpy="3.14159 1.57079 3.14159"/>
      <inertia ixx="0.133886" ixy="0" ixz="0" iyy="0.133886" iyz="0" izz="0.0151074"/>
    </inertial>
    <collision name="ur5e1__upper_arm_link_collision">
      <origin xyz="0    0    0.138" rpy="1.5708  0     -1.5708"/>
      <geometry>
        <mesh filename="model://ur5e/meshes/collision/upperarm.stl" scale="1 1 1"/>
      </geometry>
    </collision>
    <visual name="ur5e1__upper_arm_link_visual">
      <origin xyz="0    0    0.138" rpy="1.5708  0     -1.5708"/>
      <geometry>
        <mesh filename="model://ur5e/meshes/visual/upperarm.stl" scale="1 1 1"/>
      </geometry>
    </visual>
  </link>
  <link name="ur5e1__wrist_1_link">
    <inertial>
      <mass value="1.219"/>
      <origin xyz="0 0 0" rpy="0 0 0"/>
      <inertia ixx="0.0025599" ixy="0" ixz="0" iyy="0.0025599" iyz="0" izz="0.0021942"/>
    </inertial>
    <collision name="ur5e1__wrist_1_link_collision">
      <origin xyz="0     0    -0.127" rpy="1.5708 0     0"/>
      <geometry>
        <mesh filename="model://ur5e/meshes/collision/wrist1.stl" scale="1 1 1"/>
      </geometry>
    </collision>
    <visual name="ur5e1__wrist_1_link_visual">
      <origin xyz="0     0    -0.127" rpy="1.5708 0     0"/>
      <geometry>
        <mesh filename="model://ur5e/meshes/visual/wrist1.stl" scale="1 1 1"/>
      </geometry>
    </visual>
  </link>
  <link name="ur5e1__wrist_2_link">
    <inertial>
      <mass value="1.219"/>
      <origin xyz="0 0 0" rpy="0 0 0"/>
      <inertia ixx="0.0025599" ixy="0" ixz="0" iyy="0.0025599" iyz="0" izz="0.0021942"/>
    </inertial>
    <collision name="ur5e1__wrist_2_link_collision">
      <origin xyz="0      0     -0.0997" rpy="0 0 0"/>
      <geometry>
        <mesh filename="model://ur5e/meshes/collision/wrist2.stl" scale="1 1 1"/>
      </geometry>
    </collision>
    <visual name="ur5e1__wrist_2_link_visual">
      <origin xyz="0      0     -0.0997" rpy="0 0 0"/>
      <geometry>
        <mesh filename="model://ur5e/meshes/visual/wrist2.dae" scale="1 1 1"/>
      </geometry>
    </visual>
  </link>
  <link name="ur5e1__wrist_3_link">
    <inertial>
      <mass value="0.1879"/>
      <origin xyz="0      0     -0.0229" rpy="0 0 0"/>
      <inertia ixx="9.89e-05" ixy="0" ixz="0" iyy="9.89e-05" iyz="0" izz="0.00013212"/>
    </inertial>
    <collision name="ur5e1__wrist_3_link_collision">
      <origin xyz="0      0     -0.0989" rpy="1.5708 0     0"/>
      <geometry>
        <mesh filename="model://ur5e/meshes/collision/wrist3.stl" scale="1 1 1"/>
      </geometry>
    </collision>
    <visual name="ur5e1__wrist_3_link_visual">
      <origin xyz="0      0     -0.0989" rpy="1.5708 0     0"/>
      <geometry>
        <mesh filename="model://ur5e/meshes/visual/wrist3.dae" scale="1 1 1"/>
      </geometry>
    </visual>
  </link>

  <!--ur5e2 part-->
  <joint name="ur5e2__elbow_joint" type="revolute">
    <parent link="ur5e2__upper_arm_link"/>
    <child link="ur5e2__forearm_link"/>
    <origin xyz="-0.425  0     0" rpy="0 0 0"/>
    <axis xyz="0 0 1"/>
    <limit lower="-3.14159" upper="3.14159" effort="150.0" velocity="3.14159"/>
  </joint>
  <joint name="ur5e2__link_0_JOINT_1" type="fixed">
    <parent link="ur5e2__link_0"/>
    <child link="ur5e2__base_link"/>
    <origin xyz="0 0 0" rpy="0      0      3.14159"/>
    <axis xyz="0 0 0"/>
    <limit lower="0" upper="0" effort="0" velocity="0"/>
  </joint>
  <joint name="ur5e2__shoulder_lift_joint" type="revolute">
    <parent link="ur5e2__shoulder_link"/>
    <child link="ur5e2__upper_arm_link"/>
    <origin xyz="0 0 0" rpy="1.5708 0     0"/>
    <axis xyz="0 0 1"/>
    <limit lower="-6.28319" upper="6.28319" effort="150.0" velocity="3.14159"/>
  </joint>
  <joint name="ur5e2__shoulder_pan_joint" type="revolute">
    <parent link="ur5e2__base_link"/>
    <child link="ur5e2__shoulder_link"/>
    <origin xyz="0     0     0.1625" rpy="0       0      -3.14159"/>
    <axis xyz="0 0 1"/>
    <limit lower="-6.28319" upper="6.28319" effort="150.0" velocity="3.14159"/>
  </joint>
  <joint name="ur5e2__wrist_1_joint" type="revolute">
    <parent link="ur5e2__forearm_link"/>
    <child link="ur5e2__wrist_1_link"/>
    <origin xyz="-0.3922   0       0.13329" rpy="0 0 0"/>
    <axis xyz="0 0 1"/>
    <limit lower="-6.28319" upper="6.28319" effort="28.0" velocity="3.14159"/>
  </joint>
  <joint name="ur5e2__wrist_2_joint" type="revolute">
    <parent link="ur5e2__wrist_1_link"/>
    <child link="ur5e2__wrist_2_link"/>
    <origin xyz="0     -0.0997  0" rpy="1.57079 0      0"/>
    <axis xyz="0 0 1"/>
    <limit lower="-6.28319" upper="6.28319" effort="28.0" velocity="3.14159"/>
  </joint>
  <joint name="ur5e2__wrist_3_joint" type="revolute">
    <parent link="ur5e2__wrist_2_link"/>
    <child link="ur5e2__wrist_3_link"/>
    <origin xyz="0     0.0996 0" rpy="-1.57079  0       0"/>
    <axis xyz="0 0 1"/>
    <limit lower="-6.28319" upper="6.28319" effort="28.0" velocity="3.14159"/>
  </joint>
  <link name="ur5e2__base_link">
    <inertial>
      <mass value="4"/>
      <origin xyz="0 0 0" rpy="0 0 0"/>
      <inertia ixx="0.00443333" ixy="0" ixz="0" iyy="0.00443333" iyz="0" izz="0.0072"/>
    </inertial>
    <collision name="ur5e2__base_link_inertia_collision">
      <origin xyz="0 0 0" rpy="0       0      -3.14159"/>
      <geometry>
        <mesh filename="model://ur5e/meshes/collision/base.stl" scale="1 1 1"/>
      </geometry>
    </collision>
    <visual name="ur5e2__base_link_inertia_visual">
      <origin xyz="0 0 0" rpy="0       0      -3.14159"/>
      <geometry>
        <mesh filename="model://ur5e/meshes/visual/base.dae" scale="1 1 1"/>
      </geometry>
    </visual>
  </link>
  <link name="ur5e2__forearm_link">
    <inertial>
      <mass value="2.275"/>
      <origin xyz="-0.1961  0      0.007" rpy="3.14159 1.57079 3.14159"/>
      <inertia ixx="0.0312094" ixy="0" ixz="0" iyy="0.0312094" iyz="0" izz="0.004095"/>
    </inertial>
    <collision name="ur5e2__forearm_link_collision">
      <origin xyz="0    0    0.007" rpy="1.5708  0     -1.5708"/>
      <geometry>
        <mesh filename="model://ur5e/meshes/collision/forearm.stl" scale="1 1 1"/>
      </geometry>
    </collision>
    <visual name="ur5e2__forearm_link_visual">
      <origin xyz="0    0    0.007" rpy="1.5708  0     -1.5708"/>
      <geometry>
        <mesh filename="model://ur5e/meshes/visual/forearm.stl" scale="1 1 1"/>
      </geometry>
    </visual>
  </link>
  <link name="ur5e2__link_0">
    <inertial>
      <mass value="1"/>
      <origin xyz="0 0 0" rpy="0 0 0"/>
      <inertia ixx="0.145833" ixy="0" ixz="0" iyy="0.145833" iyz="0" izz="0.125"/>
    </inertial>
    <visual name="ur5e2__visual">
      <origin xyz="0   0  -0.5" rpy="-2.0e-05  1.4e-04  0.0e+00"/>
      <geometry>
        <cylinder radius="0.15" length="1"/>
      </geometry>
    </visual>
  </link>
  <link name="ur5e2__shoulder_link">
    <inertial>
      <mass value="3.7"/>
      <origin xyz="0 0 0" rpy="0 0 0"/>
      <inertia ixx="0.0102675" ixy="0" ixz="0" iyy="0.0102675" iyz="0" izz="0.00666"/>
    </inertial>
    <collision name="ur5e2__shoulder_link_collision">
      <origin xyz="0 0 0" rpy="0      0      3.14159"/>
      <geometry>
        <mesh filename="model://ur5e/meshes/collision/shoulder.stl" scale="1 1 1"/>
      </geometry>
    </collision>
    <visual name="ur5e2__shoulder_link_visual">
      <origin xyz="0 0 0" rpy="0      0      3.14159"/>
      <geometry>
        <mesh filename="model://ur5e/meshes/visual/shoulder.dae" scale="1 1 1"/>
      </geometry>
    </visual>
  </link>
  <link name="ur5e2__upper_arm_link">
    <inertial>
      <mass value="8.393"/>
      <origin xyz="-0.2125  0      0.138" rpy="3.14159 1.57079 3.14159"/>
      <inertia ixx="0.133886" ixy="0" ixz="0" iyy="0.133886" iyz="0" izz="0.0151074"/>
    </inertial>
    <collision name="ur5e2__upper_arm_link_collision">
      <origin xyz="0    0    0.138" rpy="1.5708  0     -1.5708"/>
      <geometry>
        <mesh filename="model://ur5e/meshes/collision/upperarm.stl" scale="1 1 1"/>
      </geometry>
    </collision>
    <visual name="ur5e2__upper_arm_link_visual">
      <origin xyz="0    0    0.138" rpy="1.5708  0     -1.5708"/>
      <geometry>
        <mesh filename="model://ur5e/meshes/visual/upperarm.stl" scale="1 1 1"/>
      </geometry>
    </visual>
  </link>
  <link name="ur5e2__wrist_1_link">
    <inertial>
      <mass value="1.219"/>
      <origin xyz="0 0 0" rpy="0 0 0"/>
      <inertia ixx="0.0025599" ixy="0" ixz="0" iyy="0.0025599" iyz="0" izz="0.0021942"/>
    </inertial>
    <collision name="ur5e2__wrist_1_link_collision">
      <origin xyz="0     0    -0.127" rpy="1.5708 0     0"/>
      <geometry>
        <mesh filename="model://ur5e/meshes/collision/wrist1.stl" scale="1 1 1"/>
      </geometry>
    </collision>
    <visual name="ur5e2__wrist_1_link_visual">
      <origin xyz="0     0    -0.127" rpy="1.5708 0     0"/>
      <geometry>
        <mesh filename="model://ur5e/meshes/visual/wrist1.stl" scale="1 1 1"/>
      </geometry>
    </visual>
  </link>
  <link name="ur5e2__wrist_2_link">
    <inertial>
      <mass value="1.219"/>
      <origin xyz="0 0 0" rpy="0 0 0"/>
      <inertia ixx="0.0025599" ixy="0" ixz="0" iyy="0.0025599" iyz="0" izz="0.0021942"/>
    </inertial>
    <collision name="ur5e2__wrist_2_link_collision">
      <origin xyz="0      0     -0.0997" rpy="0 0 0"/>
      <geometry>
        <mesh filename="model://ur5e/meshes/collision/wrist2.stl" scale="1 1 1"/>
      </geometry>
    </collision>
    <visual name="ur5e2__wrist_2_link_visual">
      <origin xyz="0      0     -0.0997" rpy="0 0 0"/>
      <geometry>
        <mesh filename="model://ur5e/meshes/visual/wrist2.dae" scale="1 1 1"/>
      </geometry>
    </visual>
  </link>
  <link name="ur5e2__wrist_3_link">
    <inertial>
      <mass value="0.1879"/>
      <origin xyz="0      0     -0.0229" rpy="0 0 0"/>
      <inertia ixx="9.89e-05" ixy="0" ixz="0" iyy="9.89e-05" iyz="0" izz="0.00013212"/>
    </inertial>
    <collision name="ur5e2__wrist_3_link_collision">
      <origin xyz="0      0     -0.0989" rpy="1.5708 0     0"/>
      <geometry>
        <mesh filename="model://ur5e/meshes/collision/wrist3.stl" scale="1 1 1"/>
      </geometry>
    </collision>
    <visual name="ur5e2__wrist_3_link_visual">
      <origin xyz="0      0     -0.0989" rpy="1.5708 0     0"/>
      <geometry>
        <mesh filename="model://ur5e/meshes/visual/wrist3.dae" scale="1 1 1"/>
      </geometry>
    </visual>
  </link>
</robot>
