<?xml version="1.0" ?>
<robot name="ur5">
  <joint name="ur5__elbow_joint" type="revolute">
    <parent link="ur5__upper_arm_link"/>
    <child link="ur5__forearm_link"/>
    <origin rpy="0 0 0" xyz="0     -0.1197  0.425"/>
    <axis xyz="0 1 0"/>
    <limit effort="150.0" lower="-3.14159" upper="3.14159" velocity="3.15"/>
  </joint>
  <joint name="ur_pedestal_JOINT_1" type="fixed">
    <parent link="ur_pedestal"/>
    <child link="ur5__base_link"/>
    <origin rpy="0 0 0" xyz="0 0 0"/>
    <axis xyz="0 0 0"/>
    <limit effort="0" lower="0" upper="0" velocity="0"/>
  </joint>
  <joint name="ur5__shoulder_lift_joint" type="revolute">
    <parent link="ur5__shoulder_link"/>
    <child link="ur5__upper_arm_link"/>
    <origin rpy="3.14148 1.57079 3.14148" xyz="0      0.13585 0"/>
    <axis xyz="0 1 0"/>
    <limit effort="150.0" lower="-6.28319" upper="6.28319" velocity="3.15"/>
  </joint>
  <joint name="ur5__shoulder_pan_joint" type="revolute">
    <parent link="ur5__base_link"/>
    <child link="ur5__shoulder_link"/>
    <origin rpy="0 0 0" xyz="0      0      0.08915"/>
    <axis xyz="0 0 1"/>
    <limit effort="150.0" lower="-6.28319" upper="6.28319" velocity="3.15"/>
  </joint>
  <joint name="ur5__wrist_1_joint" type="revolute">
    <parent link="ur5__forearm_link"/>
    <child link="ur5__wrist_1_link"/>
    <origin rpy="0.39713 1.57078 0.39713" xyz="0      0      0.39225"/>
    <axis xyz="0 1 0"/>
    <limit effort="28.0" lower="-6.28319" upper="6.28319" velocity="3.2"/>
  </joint>
  <joint name="ur5__wrist_2_joint" type="revolute">
    <parent link="ur5__wrist_1_link"/>
    <child link="ur5__wrist_2_link"/>
    <origin rpy="0 0 0" xyz="0    0.093 0"/>
    <axis xyz="0 0 1"/>
    <limit effort="28.0" lower="-6.28319" upper="6.28319" velocity="3.2"/>
  </joint>
  <joint name="ur5__wrist_3_joint" type="revolute">
    <parent link="ur5__wrist_2_link"/>
    <child link="ur5__wrist_3_link"/>
    <origin rpy="0 0 0" xyz="0      0      0.09465"/>
    <axis xyz="0 1 0"/>
    <limit effort="28.0" lower="-6.28319" upper="6.28319" velocity="3.2"/>
  </joint>
  <link name="ur5__base_link">
    <inertial>
      <mass value="4"/>
      <origin rpy="0 0 0" xyz="0 0 0"/>
      <inertia ixx="0.00443333" ixy="0" ixz="0" iyy="0.00443333" iyz="0" izz="0.0072"/>
    </inertial>
    <collision name="ur5__base_link_collision">
      <origin rpy="0 0 0" xyz="0 0 0"/>
      <geometry>
        <mesh filename="/home/iamnotedible/RR_Project/simulation/models/ur5/meshes/ur5/collision/base.stl" scale="1 1 1"/>
      </geometry>
    </collision>
    <visual name="ur5__base_link_visual">
      <origin rpy="0 0 0" xyz="0 0 0"/>
      <geometry>
        <mesh filename="/home/iamnotedible/RR_Project/simulation/models/ur5/meshes/ur5/visual/base.dae" scale="1 1 1"/>
      </geometry>
    </visual>
  </link>
  <link name="ur5__forearm_link">
    <inertial>
      <mass value="2.275"/>
      <origin rpy="0 0 0" xyz="0   0   0.25"/>
      <inertia ixx="0.0494433" ixy="0" ixz="0" iyy="0.0494433" iyz="0" izz="0.004095"/>
    </inertial>
    <collision name="ur5__forearm_link_collision">
      <origin rpy="0 0 0" xyz="0 0 0"/>
      <geometry>
        <mesh filename="/home/iamnotedible/RR_Project/simulation/models/ur5/meshes/ur5/collision/forearm.stl" scale="1 1 1"/>
      </geometry>
    </collision>
    <visual name="ur5__forearm_link_visual">
      <origin rpy="0 0 0" xyz="0 0 0"/>
      <geometry>
        <mesh filename="/home/iamnotedible/RR_Project/simulation/models/ur5/meshes/ur5/visual/forearm.dae" scale="1 1 1"/>
      </geometry>
    </visual>
  </link>
  <link name="ur_pedestal">
    <inertial>
      <mass value="1"/>
      <origin rpy="0 0 0" xyz="0 0 0"/>
      <inertia ixx="0.145833" ixy="0" ixz="0" iyy="0.145833" iyz="0" izz="0.125"/>
    </inertial>
    <collision name="ur5__collision">
      <origin rpy="-2.0e-05  1.4e-04  0.0e+00" xyz="0   0  -0.5"/>
      <geometry>
        <cylinder length="1" radius="0.15"/>
      </geometry>
    </collision>
    <visual name="ur5__visual">
      <origin rpy="-2.0e-05  1.4e-04  0.0e+00" xyz="0   0  -0.5"/>
      <geometry>
        <cylinder length="1" radius="0.15"/>
      </geometry>
    </visual>
  </link>
  <link name="ur5__shoulder_link">
    <inertial>
      <mass value="3.7"/>
      <origin rpy="0 0 0" xyz="0 0 0"/>
      <inertia ixx="0.0102675" ixy="0" ixz="0" iyy="0.0102675" iyz="0" izz="0.00666"/>
    </inertial>
    <collision name="ur5__shoulder_link_collision">
      <origin rpy="0 0 0" xyz="0 0 0"/>
      <geometry>
        <mesh filename="/home/iamnotedible/RR_Project/simulation/models/ur5/meshes/ur5/collision/shoulder.stl" scale="1 1 1"/>
      </geometry>
    </collision>
    <visual name="ur5__shoulder_link_visual">
      <origin rpy="0 0 0" xyz="0 0 0"/>
      <geometry>
        <mesh filename="/home/iamnotedible/RR_Project/simulation/models/ur5/meshes/ur5/visual/shoulder.dae" scale="1 1 1"/>
      </geometry>
    </visual>
  </link>
  <link name="ur5__upper_arm_link">
    <inertial>
      <mass value="8.393"/>
      <origin rpy="0 0 0" xyz="0   0   0.28"/>
      <inertia ixx="0.226891" ixy="0" ixz="0" iyy="0.226891" iyz="0" izz="0.0151074"/>
    </inertial>
    <collision name="ur5__upper_arm_link_collision">
      <origin rpy="0 0 0" xyz="0 0 0"/>
      <geometry>
        <mesh filename="/home/iamnotedible/RR_Project/simulation/models/ur5/meshes/ur5/collision/upperarm.stl" scale="1 1 1"/>
      </geometry>
    </collision>
    <visual name="ur5__upper_arm_link_visual">
      <origin rpy="0 0 0" xyz="0 0 0"/>
      <geometry>
        <mesh filename="/home/iamnotedible/RR_Project/simulation/models/ur5/meshes/ur5/visual/upperarm.dae" scale="1 1 1"/>
      </geometry>
    </visual>
  </link>
  <link name="ur5__wrist_1_link">
    <inertial>
      <mass value="1.219"/>
      <origin rpy="0 0 0" xyz="0 0 0"/>
      <inertia ixx="0.111173" ixy="0" ixz="0" iyy="0.111173" iyz="0" izz="0.21942"/>
    </inertial>
    <collision name="ur5__wrist_1_link_collision">
      <origin rpy="0 0 0" xyz="0 0 0"/>
      <geometry>
        <mesh filename="/home/iamnotedible/RR_Project/simulation/models/ur5/meshes/ur5/collision/wrist1.stl" scale="1 1 1"/>
      </geometry>
    </collision>
    <visual name="ur5__wrist_1_link_visual">
      <origin rpy="0 0 0" xyz="0 0 0"/>
      <geometry>
        <mesh filename="/home/iamnotedible/RR_Project/simulation/models/ur5/meshes/ur5/visual/wrist1.dae" scale="1 1 1"/>
      </geometry>
    </visual>
  </link>
  <link name="ur5__wrist_2_link">
    <inertial>
      <mass value="1.219"/>
      <origin rpy="0 0 0" xyz="0 0 0"/>
      <inertia ixx="0.111173" ixy="0" ixz="0" iyy="0.111173" iyz="0" izz="0.21942"/>
    </inertial>
    <collision name="ur5__wrist_2_link_collision">
      <origin rpy="0 0 0" xyz="0 0 0"/>
      <geometry>
        <mesh filename="/home/iamnotedible/RR_Project/simulation/models/ur5/meshes/ur5/collision/wrist2.stl" scale="1 1 1"/>
      </geometry>
    </collision>
    <visual name="ur5__wrist_2_link_visual">
      <origin rpy="0 0 0" xyz="0 0 0"/>
      <geometry>
        <mesh filename="/home/iamnotedible/RR_Project/simulation/models/ur5/meshes/ur5/visual/wrist2.dae" scale="1 1 1"/>
      </geometry>
    </visual>
  </link>
  <link name="ur5__wrist_3_link">
    <inertial>
      <mass value="0.18791"/>
      <origin rpy="0 0 0" xyz="0 0 0"/>
      <inertia ixx="0.0171375" ixy="6.10083e-20" ixz="5.38596e-20" iyy="0.0171375" iyz="-3.42632e-08" izz="0.033823"/>
    </inertial>
    <collision name="ur5__wrist_3_link_collision">
      <origin rpy="0 0 0" xyz="0 0 0"/>
      <geometry>
        <mesh filename="/home/iamnotedible/RR_Project/simulation/models/ur5/meshes/ur5/collision/wrist3.stl" scale="1 1 1"/>
      </geometry>
    </collision>
    <visual name="ur5__wrist_3_link_visual">
      <origin rpy="0 0 0" xyz="0 0 0"/>
      <geometry>
        <mesh filename="/home/iamnotedible/RR_Project/simulation/models/ur5/meshes/ur5/visual/wrist3.dae" scale="1 1 1"/>
      </geometry>
    </visual>
  </link>
</robot>
